Traceback (most recent call last):
  File "/opt/ohpc/pub/Software/anaconda3/envs/snakemake/lib/python3.9/site-packages/pandas/core/indexes/range.py", line 351, in get_loc
    return self._range.index(new_key)
ValueError: 0 is not in range

The above exception was the direct cause of the following exception:

Traceback (most recent call last):
  File "/data/mackanholt_lab/yp/git_DAM/DAM/DAM_blips_package/blips_script.py", line 167, in <module>
    fixed2 = fix_blips2(fixed1)
  File "/data/mackanholt_lab/yp/git_DAM/DAM/DAM_blips_package/blips_script.py", line 103, in fix_blips2
    if df.loc[0 , 'Time'] != '00:00:00':
  File "/opt/ohpc/pub/Software/anaconda3/envs/snakemake/lib/python3.9/site-packages/pandas/core/indexing.py", line 889, in __getitem__
    return self._getitem_tuple(key)
  File "/opt/ohpc/pub/Software/anaconda3/envs/snakemake/lib/python3.9/site-packages/pandas/core/indexing.py", line 1060, in _getitem_tuple
    return self._getitem_lowerdim(tup)
  File "/opt/ohpc/pub/Software/anaconda3/envs/snakemake/lib/python3.9/site-packages/pandas/core/indexing.py", line 807, in _getitem_lowerdim
    section = self._getitem_axis(key, axis=i)
  File "/opt/ohpc/pub/Software/anaconda3/envs/snakemake/lib/python3.9/site-packages/pandas/core/indexing.py", line 1124, in _getitem_axis
    return self._get_label(key, axis=axis)
  File "/opt/ohpc/pub/Software/anaconda3/envs/snakemake/lib/python3.9/site-packages/pandas/core/indexing.py", line 1073, in _get_label
    return self.obj.xs(label, axis=axis)
  File "/opt/ohpc/pub/Software/anaconda3/envs/snakemake/lib/python3.9/site-packages/pandas/core/generic.py", line 3739, in xs
    loc = index.get_loc(key)
  File "/opt/ohpc/pub/Software/anaconda3/envs/snakemake/lib/python3.9/site-packages/pandas/core/indexes/range.py", line 353, in get_loc
    raise KeyError(key) from err
KeyError: 0
